[2025-03-29T03:42:03.971+0000] {taskinstance.py:1125} INFO - Dependencies all met for dep_context=non-requeueable deps ti=<TaskInstance: covertype_workflow.collect_data scheduled__2025-03-28T03:41:55.127625+00:00 [queued]>
[2025-03-29T03:42:04.014+0000] {taskinstance.py:1125} INFO - Dependencies all met for dep_context=requeueable deps ti=<TaskInstance: covertype_workflow.collect_data scheduled__2025-03-28T03:41:55.127625+00:00 [queued]>
[2025-03-29T03:42:04.016+0000] {taskinstance.py:1331} INFO - Starting attempt 1 of 2
[2025-03-29T03:42:04.061+0000] {taskinstance.py:1350} INFO - Executing <Task(PythonOperator): collect_data> on 2025-03-28 03:41:55.127625+00:00
[2025-03-29T03:42:04.094+0000] {standard_task_runner.py:57} INFO - Started process 70659 to run task
[2025-03-29T03:42:04.111+0000] {standard_task_runner.py:84} INFO - Running: ['***', 'tasks', 'run', 'covertype_workflow', 'collect_data', 'scheduled__2025-03-28T03:41:55.127625+00:00', '--job-id', '64', '--raw', '--subdir', 'DAGS_FOLDER/covertype_workflow.py', '--cfg-path', '/tmp/tmp_dp71g8z']
[2025-03-29T03:42:04.116+0000] {standard_task_runner.py:85} INFO - Job 64: Subtask collect_data
[2025-03-29T03:42:04.284+0000] {task_command.py:410} INFO - Running <TaskInstance: covertype_workflow.collect_data scheduled__2025-03-28T03:41:55.127625+00:00 [running]> on host e7a1e9f7a361
[2025-03-29T03:42:04.517+0000] {taskinstance.py:1570} INFO - Exporting env vars: AIRFLOW_CTX_DAG_OWNER='***' AIRFLOW_CTX_DAG_ID='covertype_workflow' AIRFLOW_CTX_TASK_ID='collect_data' AIRFLOW_CTX_EXECUTION_DATE='2025-03-28T03:41:55.127625+00:00' AIRFLOW_CTX_TRY_NUMBER='1' AIRFLOW_CTX_DAG_RUN_ID='scheduled__2025-03-28T03:41:55.127625+00:00'
[2025-03-29T03:42:04.679+0000] {taskinstance.py:1847} ERROR - Task failed with exception
Traceback (most recent call last):
  File "/home/airflow/.local/lib/python3.7/site-packages/airflow/operators/python.py", line 181, in execute
    return_value = self.execute_callable()
  File "/home/airflow/.local/lib/python3.7/site-packages/airflow/operators/python.py", line 198, in execute_callable
    return self.python_callable(*self.op_args, **self.op_kwargs)
  File "/opt/airflow/dags/covertype_workflow.py", line 65, in collect_covertype_data
    raise Exception(f"Error al obtener datos para el grupo {group_number}: {response.text}")
Exception: Error al obtener datos para el grupo 1: {"detail":"Ya se recolectó toda la información mínima necesaria"}
[2025-03-29T03:42:04.706+0000] {taskinstance.py:1373} INFO - Marking task as UP_FOR_RETRY. dag_id=covertype_workflow, task_id=collect_data, execution_date=20250328T034155, start_date=20250329T034203, end_date=20250329T034204
[2025-03-29T03:42:04.726+0000] {standard_task_runner.py:109} ERROR - Failed to execute job 64 for task collect_data (Error al obtener datos para el grupo 1: {"detail":"Ya se recolectó toda la información mínima necesaria"}; 70659)
[2025-03-29T03:42:04.767+0000] {local_task_job_runner.py:232} INFO - Task exited with return code 1
[2025-03-29T03:42:04.828+0000] {taskinstance.py:2674} INFO - 0 downstream tasks scheduled from follow-on schedule check
