[2025-04-01T03:42:04.049+0000] {taskinstance.py:1125} INFO - Dependencies all met for dep_context=non-requeueable deps ti=<TaskInstance: covertype_workflow.collect_data scheduled__2025-03-31T03:41:55.127625+00:00 [queued]>
[2025-04-01T03:42:04.067+0000] {taskinstance.py:1125} INFO - Dependencies all met for dep_context=requeueable deps ti=<TaskInstance: covertype_workflow.collect_data scheduled__2025-03-31T03:41:55.127625+00:00 [queued]>
[2025-04-01T03:42:04.068+0000] {taskinstance.py:1331} INFO - Starting attempt 1 of 2
[2025-04-01T03:42:04.091+0000] {taskinstance.py:1350} INFO - Executing <Task(PythonOperator): collect_data> on 2025-03-31 03:41:55.127625+00:00
[2025-04-01T03:42:04.113+0000] {standard_task_runner.py:57} INFO - Started process 8064 to run task
[2025-04-01T03:42:04.125+0000] {standard_task_runner.py:84} INFO - Running: ['***', 'tasks', 'run', 'covertype_workflow', 'collect_data', 'scheduled__2025-03-31T03:41:55.127625+00:00', '--job-id', '83', '--raw', '--subdir', 'DAGS_FOLDER/covertype_workflow.py', '--cfg-path', '/tmp/tmpgsutflsq']
[2025-04-01T03:42:04.131+0000] {standard_task_runner.py:85} INFO - Job 83: Subtask collect_data
[2025-04-01T03:42:04.267+0000] {task_command.py:410} INFO - Running <TaskInstance: covertype_workflow.collect_data scheduled__2025-03-31T03:41:55.127625+00:00 [running]> on host d3b43addc954
[2025-04-01T03:42:04.421+0000] {taskinstance.py:1570} INFO - Exporting env vars: AIRFLOW_CTX_DAG_OWNER='***' AIRFLOW_CTX_DAG_ID='covertype_workflow' AIRFLOW_CTX_TASK_ID='collect_data' AIRFLOW_CTX_EXECUTION_DATE='2025-03-31T03:41:55.127625+00:00' AIRFLOW_CTX_TRY_NUMBER='1' AIRFLOW_CTX_DAG_RUN_ID='scheduled__2025-03-31T03:41:55.127625+00:00'
[2025-04-01T03:42:04.450+0000] {taskinstance.py:1847} ERROR - Task failed with exception
Traceback (most recent call last):
  File "/home/airflow/.local/lib/python3.7/site-packages/airflow/operators/python.py", line 181, in execute
    return_value = self.execute_callable()
  File "/home/airflow/.local/lib/python3.7/site-packages/airflow/operators/python.py", line 198, in execute_callable
    return self.python_callable(*self.op_args, **self.op_kwargs)
  File "/opt/airflow/dags/covertype_workflow.py", line 49, in collect_covertype_data
    response.raise_for_status()
  File "/home/airflow/.local/lib/python3.7/site-packages/requests/models.py", line 1021, in raise_for_status
    raise HTTPError(http_error_msg, response=self)
requests.exceptions.HTTPError: 400 Client Error: Bad Request for url: http://random-data-api:80/data?group_number=1
[2025-04-01T03:42:04.487+0000] {taskinstance.py:1373} INFO - Marking task as UP_FOR_RETRY. dag_id=covertype_workflow, task_id=collect_data, execution_date=20250331T034155, start_date=20250401T034204, end_date=20250401T034204
[2025-04-01T03:42:04.522+0000] {standard_task_runner.py:109} ERROR - Failed to execute job 83 for task collect_data (400 Client Error: Bad Request for url: http://random-data-api:80/data?group_number=1; 8064)
[2025-04-01T03:42:04.574+0000] {local_task_job_runner.py:232} INFO - Task exited with return code 1
[2025-04-01T03:42:04.640+0000] {taskinstance.py:2674} INFO - 0 downstream tasks scheduled from follow-on schedule check
