[2025-03-30T03:42:02.116+0000] {taskinstance.py:1125} INFO - Dependencies all met for dep_context=non-requeueable deps ti=<TaskInstance: covertype_workflow.collect_data scheduled__2025-03-29T03:41:55.127625+00:00 [queued]>
[2025-03-30T03:42:02.133+0000] {taskinstance.py:1125} INFO - Dependencies all met for dep_context=requeueable deps ti=<TaskInstance: covertype_workflow.collect_data scheduled__2025-03-29T03:41:55.127625+00:00 [queued]>
[2025-03-30T03:42:02.133+0000] {taskinstance.py:1331} INFO - Starting attempt 1 of 2
[2025-03-30T03:42:02.153+0000] {taskinstance.py:1350} INFO - Executing <Task(PythonOperator): collect_data> on 2025-03-29 03:41:55.127625+00:00
[2025-03-30T03:42:02.174+0000] {standard_task_runner.py:57} INFO - Started process 94444 to run task
[2025-03-30T03:42:02.185+0000] {standard_task_runner.py:84} INFO - Running: ['***', 'tasks', 'run', 'covertype_workflow', 'collect_data', 'scheduled__2025-03-29T03:41:55.127625+00:00', '--job-id', '67', '--raw', '--subdir', 'DAGS_FOLDER/covertype_workflow.py', '--cfg-path', '/tmp/tmpa1ogewp1']
[2025-03-30T03:42:02.191+0000] {standard_task_runner.py:85} INFO - Job 67: Subtask collect_data
[2025-03-30T03:42:02.306+0000] {task_command.py:410} INFO - Running <TaskInstance: covertype_workflow.collect_data scheduled__2025-03-29T03:41:55.127625+00:00 [running]> on host e7a1e9f7a361
[2025-03-30T03:42:02.465+0000] {taskinstance.py:1570} INFO - Exporting env vars: AIRFLOW_CTX_DAG_OWNER='***' AIRFLOW_CTX_DAG_ID='covertype_workflow' AIRFLOW_CTX_TASK_ID='collect_data' AIRFLOW_CTX_EXECUTION_DATE='2025-03-29T03:41:55.127625+00:00' AIRFLOW_CTX_TRY_NUMBER='1' AIRFLOW_CTX_DAG_RUN_ID='scheduled__2025-03-29T03:41:55.127625+00:00'
[2025-03-30T03:42:02.502+0000] {taskinstance.py:1847} ERROR - Task failed with exception
Traceback (most recent call last):
  File "/home/airflow/.local/lib/python3.7/site-packages/airflow/operators/python.py", line 181, in execute
    return_value = self.execute_callable()
  File "/home/airflow/.local/lib/python3.7/site-packages/airflow/operators/python.py", line 198, in execute_callable
    return self.python_callable(*self.op_args, **self.op_kwargs)
  File "/opt/airflow/dags/covertype_workflow.py", line 65, in collect_covertype_data
    raise Exception(f"Error al obtener datos para el grupo {group_number}: {response.text}")
Exception: Error al obtener datos para el grupo 1: {"detail":"Ya se recolectó toda la información mínima necesaria"}
[2025-03-30T03:42:02.548+0000] {taskinstance.py:1373} INFO - Marking task as UP_FOR_RETRY. dag_id=covertype_workflow, task_id=collect_data, execution_date=20250329T034155, start_date=20250330T034202, end_date=20250330T034202
[2025-03-30T03:42:02.566+0000] {standard_task_runner.py:109} ERROR - Failed to execute job 67 for task collect_data (Error al obtener datos para el grupo 1: {"detail":"Ya se recolectó toda la información mínima necesaria"}; 94444)
[2025-03-30T03:42:02.635+0000] {local_task_job_runner.py:232} INFO - Task exited with return code 1
[2025-03-30T03:42:02.685+0000] {taskinstance.py:2674} INFO - 0 downstream tasks scheduled from follow-on schedule check
