[2025-03-31T19:40:36.567+0000] {taskinstance.py:1125} INFO - Dependencies all met for dep_context=non-requeueable deps ti=<TaskInstance: covertype_workflow.collect_data manual__2025-03-31T19:40:24.901396+00:00 [queued]>
[2025-03-31T19:40:36.595+0000] {taskinstance.py:1125} INFO - Dependencies all met for dep_context=requeueable deps ti=<TaskInstance: covertype_workflow.collect_data manual__2025-03-31T19:40:24.901396+00:00 [queued]>
[2025-03-31T19:40:36.596+0000] {taskinstance.py:1331} INFO - Starting attempt 1 of 2
[2025-03-31T19:40:36.621+0000] {taskinstance.py:1350} INFO - Executing <Task(PythonOperator): collect_data> on 2025-03-31 19:40:24.901396+00:00
[2025-03-31T19:40:36.654+0000] {standard_task_runner.py:57} INFO - Started process 110 to run task
[2025-03-31T19:40:36.674+0000] {standard_task_runner.py:84} INFO - Running: ['***', 'tasks', 'run', 'covertype_workflow', 'collect_data', 'manual__2025-03-31T19:40:24.901396+00:00', '--job-id', '80', '--raw', '--subdir', 'DAGS_FOLDER/covertype_workflow.py', '--cfg-path', '/tmp/tmpdspqlt3e']
[2025-03-31T19:40:36.682+0000] {standard_task_runner.py:85} INFO - Job 80: Subtask collect_data
[2025-03-31T19:40:36.868+0000] {task_command.py:410} INFO - Running <TaskInstance: covertype_workflow.collect_data manual__2025-03-31T19:40:24.901396+00:00 [running]> on host d3b43addc954
[2025-03-31T19:40:37.216+0000] {taskinstance.py:1570} INFO - Exporting env vars: AIRFLOW_CTX_DAG_OWNER='***' AIRFLOW_CTX_DAG_ID='covertype_workflow' AIRFLOW_CTX_TASK_ID='collect_data' AIRFLOW_CTX_EXECUTION_DATE='2025-03-31T19:40:24.901396+00:00' AIRFLOW_CTX_TRY_NUMBER='1' AIRFLOW_CTX_DAG_RUN_ID='manual__2025-03-31T19:40:24.901396+00:00'
[2025-03-31T19:40:37.245+0000] {taskinstance.py:1847} ERROR - Task failed with exception
Traceback (most recent call last):
  File "/home/airflow/.local/lib/python3.7/site-packages/airflow/operators/python.py", line 181, in execute
    return_value = self.execute_callable()
  File "/home/airflow/.local/lib/python3.7/site-packages/airflow/operators/python.py", line 198, in execute_callable
    return self.python_callable(*self.op_args, **self.op_kwargs)
  File "/opt/airflow/dags/covertype_workflow.py", line 49, in collect_covertype_data
    response.raise_for_status()
  File "/home/airflow/.local/lib/python3.7/site-packages/requests/models.py", line 1021, in raise_for_status
    raise HTTPError(http_error_msg, response=self)
requests.exceptions.HTTPError: 400 Client Error: Bad Request for url: http://random-data-api:80/data?group_number=1
[2025-03-31T19:40:37.276+0000] {taskinstance.py:1373} INFO - Marking task as UP_FOR_RETRY. dag_id=covertype_workflow, task_id=collect_data, execution_date=20250331T194024, start_date=20250331T194036, end_date=20250331T194037
[2025-03-31T19:40:37.303+0000] {standard_task_runner.py:109} ERROR - Failed to execute job 80 for task collect_data (400 Client Error: Bad Request for url: http://random-data-api:80/data?group_number=1; 110)
[2025-03-31T19:40:37.373+0000] {local_task_job_runner.py:232} INFO - Task exited with return code 1
[2025-03-31T19:40:37.457+0000] {taskinstance.py:2674} INFO - 0 downstream tasks scheduled from follow-on schedule check
