[2025-04-01T06:36:05.663+0000] {taskinstance.py:1125} INFO - Dependencies all met for dep_context=non-requeueable deps ti=<TaskInstance: covertype_workflow.train_models manual__2025-04-01T06:35:25.998458+00:00 [queued]>
[2025-04-01T06:36:05.676+0000] {taskinstance.py:1125} INFO - Dependencies all met for dep_context=requeueable deps ti=<TaskInstance: covertype_workflow.train_models manual__2025-04-01T06:35:25.998458+00:00 [queued]>
[2025-04-01T06:36:05.677+0000] {taskinstance.py:1331} INFO - Starting attempt 1 of 2
[2025-04-01T06:36:05.693+0000] {taskinstance.py:1350} INFO - Executing <Task(PythonOperator): train_models> on 2025-04-01 06:35:25.998458+00:00
[2025-04-01T06:36:05.721+0000] {standard_task_runner.py:57} INFO - Started process 121 to run task
[2025-04-01T06:36:05.736+0000] {standard_task_runner.py:84} INFO - Running: ['***', 'tasks', 'run', 'covertype_workflow', 'train_models', 'manual__2025-04-01T06:35:25.998458+00:00', '--job-id', '126', '--raw', '--subdir', 'DAGS_FOLDER/covertype_workflow.py', '--cfg-path', '/tmp/tmph5qqttq4']
[2025-04-01T06:36:05.745+0000] {standard_task_runner.py:85} INFO - Job 126: Subtask train_models
[2025-04-01T06:36:05.859+0000] {task_command.py:410} INFO - Running <TaskInstance: covertype_workflow.train_models manual__2025-04-01T06:35:25.998458+00:00 [running]> on host 15130d1ab4b8
[2025-04-01T06:36:06.027+0000] {taskinstance.py:1568} INFO - Exporting env vars: AIRFLOW_CTX_DAG_OWNER='***' AIRFLOW_CTX_DAG_ID='covertype_workflow' AIRFLOW_CTX_TASK_ID='train_models' AIRFLOW_CTX_EXECUTION_DATE='2025-04-01T06:35:25.998458+00:00' AIRFLOW_CTX_TRY_NUMBER='1' AIRFLOW_CTX_DAG_RUN_ID='manual__2025-04-01T06:35:25.998458+00:00'
[2025-04-01T06:36:09.094+0000] {logging_mixin.py:149} WARNING - 2025/04/01 06:36:09 WARNING mlflow.utils.git_utils: Failed to import Git (the Git executable is probably not on your PATH), so Git SHA is not available. Error: Failed to initialize: Bad git executable.
The git executable must be specified in one of the following ways:
    - be included in your $PATH
    - be set via $GIT_PYTHON_GIT_EXECUTABLE
    - explicitly set via git.refresh(<full-path-to-git-executable>)

All git commands will error until this is rectified.

This initial message can be silenced or aggravated in the future by setting the
$GIT_PYTHON_REFRESH environment variable. Use one of the following values:
    - quiet|q|silence|s|silent|none|n|0: for no message or exception
    - warn|w|warning|log|l|1: for a warning message (logging level CRITICAL, displayed by default)
    - error|e|exception|raise|r|2: for a raised exception

Example:
    export GIT_PYTHON_REFRESH=quiet
[2025-04-01T06:36:43.326+0000] {warnings.py:109} WARNING - /home/***/.local/lib/python3.9/site-packages/_distutils_hack/__init__.py:33: UserWarning: Setuptools is replacing distutils.
  warnings.warn("Setuptools is replacing distutils.")

[2025-04-01T06:36:44.394+0000] {credentials.py:1124} INFO - Found credentials in environment variables.
[2025-04-01T06:37:58.594+0000] {job.py:213} ERROR - Job heartbeat got an exception
Traceback (most recent call last):
  File "/home/airflow/.local/lib/python3.9/site-packages/sqlalchemy/engine/base.py", line 3361, in _wrap_pool_connect
    return fn()
  File "/home/airflow/.local/lib/python3.9/site-packages/sqlalchemy/pool/base.py", line 327, in connect
    return _ConnectionFairy._checkout(self)
  File "/home/airflow/.local/lib/python3.9/site-packages/sqlalchemy/pool/base.py", line 894, in _checkout
    fairy = _ConnectionRecord.checkout(pool)
  File "/home/airflow/.local/lib/python3.9/site-packages/sqlalchemy/pool/base.py", line 493, in checkout
    rec = pool._do_get()
  File "/home/airflow/.local/lib/python3.9/site-packages/sqlalchemy/pool/impl.py", line 256, in _do_get
    return self._create_connection()
  File "/home/airflow/.local/lib/python3.9/site-packages/sqlalchemy/pool/base.py", line 273, in _create_connection
    return _ConnectionRecord(self)
  File "/home/airflow/.local/lib/python3.9/site-packages/sqlalchemy/pool/base.py", line 388, in __init__
    self.__connect()
  File "/home/airflow/.local/lib/python3.9/site-packages/sqlalchemy/pool/base.py", line 691, in __connect
    pool.logger.debug("Error on connect(): %s", e)
  File "/home/airflow/.local/lib/python3.9/site-packages/sqlalchemy/util/langhelpers.py", line 70, in __exit__
    compat.raise_(
  File "/home/airflow/.local/lib/python3.9/site-packages/sqlalchemy/util/compat.py", line 211, in raise_
    raise exception
  File "/home/airflow/.local/lib/python3.9/site-packages/sqlalchemy/pool/base.py", line 686, in __connect
    self.dbapi_connection = connection = pool._invoke_creator(self)
  File "/home/airflow/.local/lib/python3.9/site-packages/sqlalchemy/engine/create.py", line 574, in connect
    return dialect.connect(*cargs, **cparams)
  File "/home/airflow/.local/lib/python3.9/site-packages/sqlalchemy/engine/default.py", line 598, in connect
    return self.dbapi.connect(*cargs, **cparams)
  File "/home/airflow/.local/lib/python3.9/site-packages/psycopg2/__init__.py", line 122, in connect
    conn = _connect(dsn, connection_factory=connection_factory, **kwasync)
psycopg2.OperationalError: could not translate host name "postgres" to address: Temporary failure in name resolution


The above exception was the direct cause of the following exception:

Traceback (most recent call last):
  File "/home/airflow/.local/lib/python3.9/site-packages/airflow/jobs/job.py", line 184, in heartbeat
    session.merge(self)
  File "/home/airflow/.local/lib/python3.9/site-packages/sqlalchemy/orm/session.py", line 3053, in merge
    return self._merge(
  File "/home/airflow/.local/lib/python3.9/site-packages/sqlalchemy/orm/session.py", line 3133, in _merge
    merged = self.get(
  File "/home/airflow/.local/lib/python3.9/site-packages/sqlalchemy/orm/session.py", line 2850, in get
    return self._get_impl(
  File "/home/airflow/.local/lib/python3.9/site-packages/sqlalchemy/orm/session.py", line 2972, in _get_impl
    return db_load_fn(
  File "/home/airflow/.local/lib/python3.9/site-packages/sqlalchemy/orm/loading.py", line 530, in load_on_pk_identity
    session.execute(
  File "/home/airflow/.local/lib/python3.9/site-packages/sqlalchemy/orm/session.py", line 1713, in execute
    conn = self._connection_for_bind(bind)
  File "/home/airflow/.local/lib/python3.9/site-packages/sqlalchemy/orm/session.py", line 1552, in _connection_for_bind
    return self._transaction._connection_for_bind(
  File "/home/airflow/.local/lib/python3.9/site-packages/sqlalchemy/orm/session.py", line 747, in _connection_for_bind
    conn = bind.connect()
  File "/home/airflow/.local/lib/python3.9/site-packages/sqlalchemy/engine/base.py", line 3315, in connect
    return self._connection_cls(self, close_with_result=close_with_result)
  File "/home/airflow/.local/lib/python3.9/site-packages/sqlalchemy/engine/base.py", line 96, in __init__
    else engine.raw_connection()
  File "/home/airflow/.local/lib/python3.9/site-packages/sqlalchemy/engine/base.py", line 3394, in raw_connection
    return self._wrap_pool_connect(self.pool.connect, _connection)
  File "/home/airflow/.local/lib/python3.9/site-packages/sqlalchemy/engine/base.py", line 3364, in _wrap_pool_connect
    Connection._handle_dbapi_exception_noconnection(
  File "/home/airflow/.local/lib/python3.9/site-packages/sqlalchemy/engine/base.py", line 2198, in _handle_dbapi_exception_noconnection
    util.raise_(
  File "/home/airflow/.local/lib/python3.9/site-packages/sqlalchemy/util/compat.py", line 211, in raise_
    raise exception
  File "/home/airflow/.local/lib/python3.9/site-packages/sqlalchemy/engine/base.py", line 3361, in _wrap_pool_connect
    return fn()
  File "/home/airflow/.local/lib/python3.9/site-packages/sqlalchemy/pool/base.py", line 327, in connect
    return _ConnectionFairy._checkout(self)
  File "/home/airflow/.local/lib/python3.9/site-packages/sqlalchemy/pool/base.py", line 894, in _checkout
    fairy = _ConnectionRecord.checkout(pool)
  File "/home/airflow/.local/lib/python3.9/site-packages/sqlalchemy/pool/base.py", line 493, in checkout
    rec = pool._do_get()
  File "/home/airflow/.local/lib/python3.9/site-packages/sqlalchemy/pool/impl.py", line 256, in _do_get
    return self._create_connection()
  File "/home/airflow/.local/lib/python3.9/site-packages/sqlalchemy/pool/base.py", line 273, in _create_connection
    return _ConnectionRecord(self)
  File "/home/airflow/.local/lib/python3.9/site-packages/sqlalchemy/pool/base.py", line 388, in __init__
    self.__connect()
  File "/home/airflow/.local/lib/python3.9/site-packages/sqlalchemy/pool/base.py", line 691, in __connect
    pool.logger.debug("Error on connect(): %s", e)
  File "/home/airflow/.local/lib/python3.9/site-packages/sqlalchemy/util/langhelpers.py", line 70, in __exit__
    compat.raise_(
  File "/home/airflow/.local/lib/python3.9/site-packages/sqlalchemy/util/compat.py", line 211, in raise_
    raise exception
  File "/home/airflow/.local/lib/python3.9/site-packages/sqlalchemy/pool/base.py", line 686, in __connect
    self.dbapi_connection = connection = pool._invoke_creator(self)
  File "/home/airflow/.local/lib/python3.9/site-packages/sqlalchemy/engine/create.py", line 574, in connect
    return dialect.connect(*cargs, **cparams)
  File "/home/airflow/.local/lib/python3.9/site-packages/sqlalchemy/engine/default.py", line 598, in connect
    return self.dbapi.connect(*cargs, **cparams)
  File "/home/airflow/.local/lib/python3.9/site-packages/psycopg2/__init__.py", line 122, in connect
    conn = _connect(dsn, connection_factory=connection_factory, **kwasync)
sqlalchemy.exc.OperationalError: (psycopg2.OperationalError) could not translate host name "postgres" to address: Temporary failure in name resolution

(Background on this error at: https://sqlalche.me/e/14/e3q8)
[2025-04-01T06:51:54.607+0000] {logging_mixin.py:149} WARNING - Successfully registered model 'CovertypeModel'.
[2025-04-01T06:51:54.721+0000] {logging_mixin.py:149} WARNING - 2025/04/01 06:51:54 INFO mlflow.tracking._model_registry.client: Waiting up to 300 seconds for model version to finish creation.                     Model name: CovertypeModel, version 1
[2025-04-01T06:51:54.721+0000] {logging_mixin.py:149} WARNING - Created version '1' of model 'CovertypeModel'.
[2025-04-01T06:51:54.727+0000] {covertype_workflow.py:201} INFO - Registrado en Model Registry: CovertypeModel v1
[2025-04-01T06:51:54.793+0000] {covertype_workflow.py:210} INFO - Mejor modelo: random_forest, acc=0.8572289156626506, stage=Production
[2025-04-01T06:51:54.794+0000] {python.py:183} INFO - Done. Returned value was: None
[2025-04-01T06:51:54.833+0000] {taskinstance.py:1368} INFO - Marking task as SUCCESS. dag_id=covertype_workflow, task_id=train_models, execution_date=20250401T063525, start_date=20250401T063605, end_date=20250401T065154
[2025-04-01T06:51:55.132+0000] {local_task_job_runner.py:232} INFO - Task exited with return code 0
[2025-04-01T06:51:55.181+0000] {taskinstance.py:2674} INFO - 1 downstream tasks scheduled from follow-on schedule check
