[2025-04-01T04:31:29.977+0000] {taskinstance.py:1125} INFO - Dependencies all met for dep_context=non-requeueable deps ti=<TaskInstance: covertype_workflow.train_models manual__2025-04-01T04:31:09.883653+00:00 [queued]>
[2025-04-01T04:31:29.995+0000] {taskinstance.py:1125} INFO - Dependencies all met for dep_context=requeueable deps ti=<TaskInstance: covertype_workflow.train_models manual__2025-04-01T04:31:09.883653+00:00 [queued]>
[2025-04-01T04:31:29.996+0000] {taskinstance.py:1331} INFO - Starting attempt 1 of 2
[2025-04-01T04:31:30.018+0000] {taskinstance.py:1350} INFO - Executing <Task(PythonOperator): train_models> on 2025-04-01 04:31:09.883653+00:00
[2025-04-01T04:31:30.049+0000] {standard_task_runner.py:57} INFO - Started process 431 to run task
[2025-04-01T04:31:30.076+0000] {standard_task_runner.py:84} INFO - Running: ['***', 'tasks', 'run', 'covertype_workflow', 'train_models', 'manual__2025-04-01T04:31:09.883653+00:00', '--job-id', '102', '--raw', '--subdir', 'DAGS_FOLDER/covertype_workflow.py', '--cfg-path', '/tmp/tmp6giub1fb']
[2025-04-01T04:31:30.089+0000] {standard_task_runner.py:85} INFO - Job 102: Subtask train_models
[2025-04-01T04:31:30.376+0000] {task_command.py:410} INFO - Running <TaskInstance: covertype_workflow.train_models manual__2025-04-01T04:31:09.883653+00:00 [running]> on host fa1ab66db115
[2025-04-01T04:31:30.917+0000] {taskinstance.py:1570} INFO - Exporting env vars: AIRFLOW_CTX_DAG_OWNER='***' AIRFLOW_CTX_DAG_ID='covertype_workflow' AIRFLOW_CTX_TASK_ID='train_models' AIRFLOW_CTX_EXECUTION_DATE='2025-04-01T04:31:09.883653+00:00' AIRFLOW_CTX_TRY_NUMBER='1' AIRFLOW_CTX_DAG_RUN_ID='manual__2025-04-01T04:31:09.883653+00:00'
[2025-04-01T04:31:31.038+0000] {taskinstance.py:1847} ERROR - Task failed with exception
Traceback (most recent call last):
  File "/home/airflow/.local/lib/python3.7/site-packages/sqlalchemy/engine/base.py", line 1901, in _execute_context
    cursor, statement, parameters, context
  File "/home/airflow/.local/lib/python3.7/site-packages/sqlalchemy/engine/default.py", line 736, in do_execute
    cursor.execute(statement, parameters)
  File "/home/airflow/.local/lib/python3.7/site-packages/pymysql/cursors.py", line 153, in execute
    result = self._query(query)
  File "/home/airflow/.local/lib/python3.7/site-packages/pymysql/cursors.py", line 322, in _query
    conn.query(q)
  File "/home/airflow/.local/lib/python3.7/site-packages/pymysql/connections.py", line 563, in query
    self._affected_rows = self._read_query_result(unbuffered=unbuffered)
  File "/home/airflow/.local/lib/python3.7/site-packages/pymysql/connections.py", line 825, in _read_query_result
    result.read()
  File "/home/airflow/.local/lib/python3.7/site-packages/pymysql/connections.py", line 1199, in read
    first_packet = self.connection._read_packet()
  File "/home/airflow/.local/lib/python3.7/site-packages/pymysql/connections.py", line 775, in _read_packet
    packet.raise_for_error()
  File "/home/airflow/.local/lib/python3.7/site-packages/pymysql/protocol.py", line 219, in raise_for_error
    err.raise_mysql_exception(self._data)
  File "/home/airflow/.local/lib/python3.7/site-packages/pymysql/err.py", line 150, in raise_mysql_exception
    raise errorclass(errno, errval)
pymysql.err.ProgrammingError: (1146, "Table 'model_db.covertype_preprocessed' doesn't exist")

The above exception was the direct cause of the following exception:

Traceback (most recent call last):
  File "/home/airflow/.local/lib/python3.7/site-packages/airflow/operators/python.py", line 181, in execute
    return_value = self.execute_callable()
  File "/home/airflow/.local/lib/python3.7/site-packages/airflow/operators/python.py", line 198, in execute_callable
    return self.python_callable(*self.op_args, **self.op_kwargs)
  File "/opt/airflow/dags/covertype_workflow.py", line 156, in train_and_log_models
    df = pd.read_sql('SELECT * FROM covertype_preprocessed', con=engine)
  File "/home/airflow/.local/lib/python3.7/site-packages/pandas/io/sql.py", line 634, in read_sql
    chunksize=chunksize,
  File "/home/airflow/.local/lib/python3.7/site-packages/pandas/io/sql.py", line 1579, in read_query
    result = self.execute(*args)
  File "/home/airflow/.local/lib/python3.7/site-packages/pandas/io/sql.py", line 1424, in execute
    return self.connectable.execution_options().execute(*args, **kwargs)
  File "<string>", line 2, in execute
  File "/home/airflow/.local/lib/python3.7/site-packages/sqlalchemy/util/deprecations.py", line 468, in warned
    return fn(*args, **kwargs)
  File "/home/airflow/.local/lib/python3.7/site-packages/sqlalchemy/engine/base.py", line 3257, in execute
    return connection.execute(statement, *multiparams, **params)
  File "/home/airflow/.local/lib/python3.7/site-packages/sqlalchemy/engine/base.py", line 1370, in execute
    future=False,
  File "/home/airflow/.local/lib/python3.7/site-packages/sqlalchemy/engine/base.py", line 1676, in _exec_driver_sql
    distilled_parameters,
  File "/home/airflow/.local/lib/python3.7/site-packages/sqlalchemy/engine/base.py", line 1944, in _execute_context
    e, statement, parameters, cursor, context
  File "/home/airflow/.local/lib/python3.7/site-packages/sqlalchemy/engine/base.py", line 2125, in _handle_dbapi_exception
    sqlalchemy_exception, with_traceback=exc_info[2], from_=e
  File "/home/airflow/.local/lib/python3.7/site-packages/sqlalchemy/util/compat.py", line 211, in raise_
    raise exception
  File "/home/airflow/.local/lib/python3.7/site-packages/sqlalchemy/engine/base.py", line 1901, in _execute_context
    cursor, statement, parameters, context
  File "/home/airflow/.local/lib/python3.7/site-packages/sqlalchemy/engine/default.py", line 736, in do_execute
    cursor.execute(statement, parameters)
  File "/home/airflow/.local/lib/python3.7/site-packages/pymysql/cursors.py", line 153, in execute
    result = self._query(query)
  File "/home/airflow/.local/lib/python3.7/site-packages/pymysql/cursors.py", line 322, in _query
    conn.query(q)
  File "/home/airflow/.local/lib/python3.7/site-packages/pymysql/connections.py", line 563, in query
    self._affected_rows = self._read_query_result(unbuffered=unbuffered)
  File "/home/airflow/.local/lib/python3.7/site-packages/pymysql/connections.py", line 825, in _read_query_result
    result.read()
  File "/home/airflow/.local/lib/python3.7/site-packages/pymysql/connections.py", line 1199, in read
    first_packet = self.connection._read_packet()
  File "/home/airflow/.local/lib/python3.7/site-packages/pymysql/connections.py", line 775, in _read_packet
    packet.raise_for_error()
  File "/home/airflow/.local/lib/python3.7/site-packages/pymysql/protocol.py", line 219, in raise_for_error
    err.raise_mysql_exception(self._data)
  File "/home/airflow/.local/lib/python3.7/site-packages/pymysql/err.py", line 150, in raise_mysql_exception
    raise errorclass(errno, errval)
sqlalchemy.exc.ProgrammingError: (pymysql.err.ProgrammingError) (1146, "Table 'model_db.covertype_preprocessed' doesn't exist")
[SQL: SELECT * FROM covertype_preprocessed]
(Background on this error at: https://sqlalche.me/e/14/f405)
[2025-04-01T04:31:31.111+0000] {taskinstance.py:1373} INFO - Marking task as UP_FOR_RETRY. dag_id=covertype_workflow, task_id=train_models, execution_date=20250401T043109, start_date=20250401T043129, end_date=20250401T043131
[2025-04-01T04:31:31.155+0000] {standard_task_runner.py:109} ERROR - Failed to execute job 102 for task train_models ((pymysql.err.ProgrammingError) (1146, "Table 'model_db.covertype_preprocessed' doesn't exist")
[SQL: SELECT * FROM covertype_preprocessed]
(Background on this error at: https://sqlalche.me/e/14/f405); 431)
[2025-04-01T04:31:31.202+0000] {local_task_job_runner.py:232} INFO - Task exited with return code 1
[2025-04-01T04:31:31.276+0000] {taskinstance.py:2674} INFO - 0 downstream tasks scheduled from follow-on schedule check
