[2025-03-25T04:47:14.994+0000] {taskinstance.py:1125} INFO - Dependencies all met for dep_context=non-requeueable deps ti=<TaskInstance: covertype_workflow.collect_data manual__2025-03-25T04:41:58.267096+00:00 [queued]>
[2025-03-25T04:47:15.011+0000] {taskinstance.py:1125} INFO - Dependencies all met for dep_context=requeueable deps ti=<TaskInstance: covertype_workflow.collect_data manual__2025-03-25T04:41:58.267096+00:00 [queued]>
[2025-03-25T04:47:15.012+0000] {taskinstance.py:1331} INFO - Starting attempt 2 of 2
[2025-03-25T04:47:15.033+0000] {taskinstance.py:1350} INFO - Executing <Task(PythonOperator): collect_data> on 2025-03-25 04:41:58.267096+00:00
[2025-03-25T04:47:15.053+0000] {standard_task_runner.py:57} INFO - Started process 186 to run task
[2025-03-25T04:47:15.063+0000] {standard_task_runner.py:84} INFO - Running: ['***', 'tasks', 'run', 'covertype_workflow', 'collect_data', 'manual__2025-03-25T04:41:58.267096+00:00', '--job-id', '16', '--raw', '--subdir', 'DAGS_FOLDER/covertype_workflow.py', '--cfg-path', '/tmp/tmp939678kt']
[2025-03-25T04:47:15.069+0000] {standard_task_runner.py:85} INFO - Job 16: Subtask collect_data
[2025-03-25T04:47:15.197+0000] {task_command.py:410} INFO - Running <TaskInstance: covertype_workflow.collect_data manual__2025-03-25T04:41:58.267096+00:00 [running]> on host ad728168efcb
[2025-03-25T04:47:15.389+0000] {taskinstance.py:1570} INFO - Exporting env vars: AIRFLOW_CTX_DAG_OWNER='***' AIRFLOW_CTX_DAG_ID='covertype_workflow' AIRFLOW_CTX_TASK_ID='collect_data' AIRFLOW_CTX_EXECUTION_DATE='2025-03-25T04:41:58.267096+00:00' AIRFLOW_CTX_TRY_NUMBER='2' AIRFLOW_CTX_DAG_RUN_ID='manual__2025-03-25T04:41:58.267096+00:00'
[2025-03-25T04:47:18.486+0000] {taskinstance.py:1847} ERROR - Task failed with exception
Traceback (most recent call last):
  File "/home/airflow/.local/lib/python3.7/site-packages/airflow/operators/python.py", line 181, in execute
    return_value = self.execute_callable()
  File "/home/airflow/.local/lib/python3.7/site-packages/airflow/operators/python.py", line 198, in execute_callable
    return self.python_callable(*self.op_args, **self.op_kwargs)
  File "/opt/airflow/dags/covertype_workflow.py", line 65, in collect_covertype_data
    raise Exception(f"Error al obtener datos para el grupo {group_number}: {response.text}")
Exception: Error al obtener datos para el grupo 10: Internal Server Error
[2025-03-25T04:47:18.507+0000] {taskinstance.py:1373} INFO - Marking task as FAILED. dag_id=covertype_workflow, task_id=collect_data, execution_date=20250325T044158, start_date=20250325T044714, end_date=20250325T044718
[2025-03-25T04:47:18.525+0000] {standard_task_runner.py:109} ERROR - Failed to execute job 16 for task collect_data (Error al obtener datos para el grupo 10: Internal Server Error; 186)
[2025-03-25T04:47:18.604+0000] {local_task_job_runner.py:232} INFO - Task exited with return code 1
[2025-03-25T04:47:18.665+0000] {taskinstance.py:2674} INFO - 0 downstream tasks scheduled from follow-on schedule check
