[2025-04-01T04:26:15.629+0000] {taskinstance.py:1125} INFO - Dependencies all met for dep_context=non-requeueable deps ti=<TaskInstance: covertype_workflow.preprocess_data manual__2025-04-01T04:25:59.406345+00:00 [queued]>
[2025-04-01T04:26:15.661+0000] {taskinstance.py:1125} INFO - Dependencies all met for dep_context=requeueable deps ti=<TaskInstance: covertype_workflow.preprocess_data manual__2025-04-01T04:25:59.406345+00:00 [queued]>
[2025-04-01T04:26:15.661+0000] {taskinstance.py:1331} INFO - Starting attempt 1 of 2
[2025-04-01T04:26:15.699+0000] {taskinstance.py:1350} INFO - Executing <Task(PythonOperator): preprocess_data> on 2025-04-01 04:25:59.406345+00:00
[2025-04-01T04:26:15.728+0000] {standard_task_runner.py:57} INFO - Started process 336 to run task
[2025-04-01T04:26:15.747+0000] {standard_task_runner.py:84} INFO - Running: ['***', 'tasks', 'run', 'covertype_workflow', 'preprocess_data', 'manual__2025-04-01T04:25:59.406345+00:00', '--job-id', '97', '--raw', '--subdir', 'DAGS_FOLDER/covertype_workflow.py', '--cfg-path', '/tmp/tmpryxs4x_y']
[2025-04-01T04:26:15.762+0000] {standard_task_runner.py:85} INFO - Job 97: Subtask preprocess_data
[2025-04-01T04:26:15.922+0000] {task_command.py:410} INFO - Running <TaskInstance: covertype_workflow.preprocess_data manual__2025-04-01T04:25:59.406345+00:00 [running]> on host fa1ab66db115
[2025-04-01T04:26:16.106+0000] {taskinstance.py:1570} INFO - Exporting env vars: AIRFLOW_CTX_DAG_OWNER='***' AIRFLOW_CTX_DAG_ID='covertype_workflow' AIRFLOW_CTX_TASK_ID='preprocess_data' AIRFLOW_CTX_EXECUTION_DATE='2025-04-01T04:25:59.406345+00:00' AIRFLOW_CTX_TRY_NUMBER='1' AIRFLOW_CTX_DAG_RUN_ID='manual__2025-04-01T04:25:59.406345+00:00'
[2025-04-01T04:26:16.208+0000] {taskinstance.py:1847} ERROR - Task failed with exception
Traceback (most recent call last):
  File "/home/airflow/.local/lib/python3.7/site-packages/airflow/operators/python.py", line 181, in execute
    return_value = self.execute_callable()
  File "/home/airflow/.local/lib/python3.7/site-packages/airflow/operators/python.py", line 198, in execute_callable
    return self.python_callable(*self.op_args, **self.op_kwargs)
  File "/opt/airflow/dags/covertype_workflow.py", line 128, in preprocess_covertype_data
    df_numeric[num_cols] = scaler.fit_transform(df_numeric[num_cols])
  File "/home/airflow/.local/lib/python3.7/site-packages/sklearn/base.py", line 852, in fit_transform
    return self.fit(X, **fit_params).transform(X)
  File "/home/airflow/.local/lib/python3.7/site-packages/sklearn/preprocessing/_data.py", line 806, in fit
    return self.partial_fit(X, y, sample_weight)
  File "/home/airflow/.local/lib/python3.7/site-packages/sklearn/preprocessing/_data.py", line 847, in partial_fit
    reset=first_call,
  File "/home/airflow/.local/lib/python3.7/site-packages/sklearn/base.py", line 566, in _validate_data
    X = check_array(X, **check_params)
  File "/home/airflow/.local/lib/python3.7/site-packages/sklearn/utils/validation.py", line 808, in check_array
    % (n_samples, array.shape, ensure_min_samples, context)
ValueError: Found array with 0 sample(s) (shape=(0, 10)) while a minimum of 1 is required by StandardScaler.
[2025-04-01T04:26:16.261+0000] {taskinstance.py:1373} INFO - Marking task as UP_FOR_RETRY. dag_id=covertype_workflow, task_id=preprocess_data, execution_date=20250401T042559, start_date=20250401T042615, end_date=20250401T042616
[2025-04-01T04:26:16.279+0000] {standard_task_runner.py:109} ERROR - Failed to execute job 97 for task preprocess_data (Found array with 0 sample(s) (shape=(0, 10)) while a minimum of 1 is required by StandardScaler.; 336)
[2025-04-01T04:26:16.313+0000] {local_task_job_runner.py:232} INFO - Task exited with return code 1
[2025-04-01T04:26:16.366+0000] {taskinstance.py:2674} INFO - 0 downstream tasks scheduled from follow-on schedule check
